<?xml version="1.0"?>

<robot xmlns:xacro="http://www.ros.org/wiki/xacro" name="Watcher">

    <link name="base_footprint"/>

    <joint name="base_joint" type="fixed">
        <parent link="base_footprint"/>
        <child link="base_link"/>
        <origin rpy="0 0 0" xyz="0 0 0.05"/>
    </joint>

    <link name="base_link">
        <visual>
            <origin rpy="0 0 0" xyz="0 0 0.1778"/>
            <geometry>
                <box size="0.6096 0.4953 0.3556"/>
            </geometry>
        </visual>
        <collision>
            <origin rpy="0 0 0" xyz="0 0 0.1778"/>
            <geometry>
                <box size="0.6096 0.4953 0.3556"/>
            </geometry>
        </collision>
    </link>

    <joint name="right_wheel_joint" type="continuous">
        <parent link="base_link"/>
        <child link="right_wheel"/>
        <axis xyz="0 1 0"/>
        <origin rpy="0 0 0" xyz="0 -0.2794 0.1778"/>
    </joint>

    <link name="right_wheel">
        <visual>
            <origin rpy="1.5708 0 0" xyz="0 0 0"/>
            <geometry>
                <cylinder radius="0.3175" length="0.0508"/>
            </geometry>
        </visual>
        <collision>
            <origin rpy="1.5708 0 0" xyz="0 0 0"/>
            <geometry>
                <cylinder radius="0.3175" length="0.0508"/>
            </geometry>
        </collision>
    </link>

    <joint name="left_wheel_joint" type="continuous">
        <parent link="base_link"/>
        <child link="left_wheel"/>
        <axis xyz="0 1 0"/>
        <origin rpy="0 0 0" xyz="0 0.2794 0.1778"/>
    </joint>

    <link name="left_wheel">
        <visual>
            <origin rpy="1.5708 0 0" xyz="0 0 0"/>
            <geometry>
                <cylinder radius="0.3175" length="0.0508"/>
            </geometry>
        </visual>
        <collision>
            <origin rpy="1.5708 0 0" xyz="0 0 0"/>
            <geometry>
                <cylinder radius="0.3175" length="0.0508"/>
            </geometry>
        </collision>
    </link>

    <joint name="chair_joint" type="fixed">
        <parent link="base_link"/>
        <child link="chair"/>
        <origin rpy="0 0 0" xyz="0 0 0.381"/>
    </joint>

    <link name="chair">
        <visual>
            <origin rpy="0 0 0" xyz="0 0 0.3556"/>
            <geometry>
                <box size="0.4826 0.508 0.7112"/>
            </geometry>
        </visual>
        <collision>
            <origin rpy="0 0 0" xyz="0 0 0.3556"/>
            <geometry>
                <box size="0.4826 0.508 0.7112"/>
            </geometry>
        </collision>
    </link>


</robot>
